<?xml version="1.0"?>
<robot name="BHR8-TC">
  <link name="base">
    <inertial>
      <mass value="1.1"/>
      <origin xyz="0 0 0"/>
      <inertia ixx="0.0001" ixy="0" ixz="0" iyy="0.0001" iyz="0" izz="0.0001"/>
    </inertial>
  </link>
  <link name="uppbody">
    <inertial>
      <mass value="21.198"/>
      <origin xyz="-0.01 0 0.303214317947705"/>
      <inertia ixx="0.68" ixy="0" ixz="0" iyy="0.64" iyz="0" izz="0.18"/>
    </inertial>
    <collision>
      <origin rpy="0 0 0" xyz="0.0 0.0 0.3"/>
      <geometry>
        <sphere radius="0.2"/>
      </geometry>
    </collision>
    <visual>
      <origin rpy="0 0 0" xyz="0 0 0"/>
      <geometry>
        <mesh filename="BHR8TC_STL/torso.stl" scale="1 1 1"/>
        <!-- <sphere radius="0.2"/> -->
      </geometry>
      <material name="grey">
        <color rgba="0.35 0.35 0.35 1"/>
      </material>
    </visual>
  </link>
  <joint name="fixed_uppbody_to_base" type="fixed">
    <parent link="uppbody"/>
    <child link="base"/>
    <origin xyz="0 0 0" rpy="0 0 0"/>
  </joint>
  <!-- <link name="larm">
    <inertial>
      <mass value="0"/>
      <origin xyz="0.019 0 -0.229"/>
      <inertia ixx="0" ixy="0" ixz="0" iyy="0" iyz="0" izz="0"/>
    </inertial>
  </link>
  <joint name="larm1" type="revolute">
    <parent link="uppbody"/>
    <child link="larm"/>
    <origin xyz="-0.042 0.272 0.411" rpy="0 0 0"/>
    <axis xyz="0 1 0"/>
    <limit effort="100.0" velocity="100.0" lower="-3.14" upper="3.14"/>
  </joint>
  <link name="rarm">
    <inertial>
      <mass value="0"/>
      <origin xyz="0.019 0 -0.229"/>
      <inertia ixx="0" ixy="0" ixz="0" iyy="0" iyz="0" izz="0"/>
    </inertial>
  </link>
  <joint name="rarm1" type="revolute">
    <parent link="uppbody"/>
    <child link="rarm"/>
    <origin xyz="-0.042 -0.272 0.411" rpy="0 0 0"/>
    <axis xyz="0 1 0"/>
    <limit effort="100.0" velocity="100.0" lower="-3.14" upper="3.14"/>
  </joint> -->
  <link name="lhip_rz">
    <inertial>
      <mass value="2.389"/>
      <origin xyz="-0.07 0.0 -0.092"/>
      <inertia ixx="0.003" ixy="0" ixz="0" iyy="0.003" iyz="0" izz="0.003"/>
    </inertial>
    <visual>
      <origin rpy="0 0 0" xyz="0 0 0"/>
      <geometry>
        <mesh filename="BHR8TC_STL/lhipyaw.stl" scale="1 1 1"/>
      </geometry>
      <material name="grey">
        <color rgba="0.35 0.35 0.35 1"/>
      </material>
    </visual>
  </link>
  <joint name="leg1_left" type="revolute">
    <parent link="base"/>
    <child link="lhip_rz"/>
    <origin xyz="0 0.1 0.03524" rpy="0 0 0"/>
    <axis xyz="0 0 1"/>
    <limit effort="100.0" velocity="100.0" lower="-3.14" upper="3.14"/>
  </joint>
  <link name="lhip_rzrx">
    <inertial>
      <mass value="2.507"/>
      <origin xyz="0.075 0.0 0.0"/>
      <inertia ixx="0.004" ixy="0" ixz="0" iyy="0.003" iyz="0" izz="0.004"/>
    </inertial>
    <visual>
      <origin rpy="0 0 0" xyz="0 0 0"/>
      <geometry>
        <mesh filename="BHR8TC_STL/lhiproll.stl" scale="1 1 1"/>
      </geometry>
      <material name="grey">
        <color rgba="0.35 0.35 0.35 1"/>
      </material>
    </visual>
  </link>
  <joint name="leg2_left" type="revolute">
    <parent link="lhip_rz"/>
    <child link="lhip_rzrx"/>
    <origin xyz="-0.066 0 -0.13924" rpy="0 0 0"/>
    <axis xyz="1 0 0"/>
    <limit effort="100.0" velocity="100.0" lower="-3.14" upper="3.14"/>
  </joint>
  <link name="lthigh">
    <inertial>
      <mass value="3.096"/>
      <origin xyz="0.02 0.0 -0.17"/>
      <inertia ixx="0.040" ixy="0" ixz="0" iyy="0.040" iyz="0" izz="0.006"/>
    </inertial>
    <visual>
      <origin rpy="0 0 0" xyz="0 0 0"/>
      <geometry>
        <mesh filename="BHR8TC_STL/lhippitch.stl" scale="1 1 1"/>
      </geometry>
      <material name="grey">
        <color rgba="0.35 0.35 0.35 1"/>
      </material>
    </visual>
  </link>
  <joint name="leg3_left" type="revolute">
    <parent link="lhip_rzrx"/>
    <child link="lthigh"/>
    <origin xyz="0.077 0.0001 0" rpy="0 0 0"/>
    <axis xyz="0 1 0"/>
    <limit effort="100.0" velocity="100.0" lower="-3.14" upper="3.14"/>
  </joint>
  <link name="lshank">
    <inertial>
      <mass value="1.914"/>
      <origin xyz="0.01 0.0 -0.15"/>
      <inertia ixx="0.02" ixy="0" ixz="0" iyy="0.02" iyz="0" izz="0.002"/>
    </inertial>
    <visual>
      <origin rpy="0 0 0" xyz="0 0 0"/>
      <geometry>
        <mesh filename="BHR8TC_STL/lkneepitch.stl" scale="1 1 1"/>
      </geometry>
      <material name="grey">
        <color rgba="0.35 0.35 0.35 1"/>
      </material>
    </visual>
  </link>
  <joint name="leg4_left" type="revolute">
    <parent link="lthigh"/>
    <child link="lshank"/>
    <origin xyz="0.00754465 -0.00336 -0.374943" rpy="0 0 0"/>
    <axis xyz="0 1 0"/>
    <limit effort="100.0" velocity="100.0" lower="-3.14" upper="3.14"/>
  </joint>
  <link name="lankle">
    <inertial>
      <mass value="0.6"/>
      <origin xyz="0.0005146 -4.289e-05 -0.04189"/>
      <inertia ixx="0.002" ixy="0" ixz="0" iyy="0.002" iyz="0" izz="0.0004"/>
    </inertial>
    <visual>
      <origin rpy="0 0 0" xyz="0 0 0"/>
      <geometry>
        <mesh filename="BHR8TC_STL/lanklepitch.stl" scale="1 1 1"/>
      </geometry>
      <material name="light_grey">
        <color rgba="0.75 0.75 0.75 1"/>
      </material>
    </visual>
    <collision>
      <origin rpy="0 0 0" xyz="0.03 0.0 -0.05"/>
      <geometry>
          <box size="0.2 0.1 0.02"/>
      </geometry>
    </collision>
  </link>
  <joint name="leg5_left" type="revolute">
    <parent link="lshank"/>
    <child link="lankle"/>
    <origin xyz="0 0 -0.35" rpy="0 0 0"/>
    <axis xyz="0 1 0"/>
    <limit effort="100.0" velocity="100.0" lower="-3.14" upper="3.14"/>
  </joint>
  
  <link name="rhip_rz">
    <inertial>
      <mass value="2.389"/>
      <origin xyz="-0.07 0.0 -0.092"/>
      <inertia ixx="0.003" ixy="0" ixz="0" iyy="0.003" iyz="0" izz="0.003"/>
    </inertial>
    <visual>
      <origin rpy="0 0 0" xyz="0 0 0"/>
      <geometry>
        <mesh filename="BHR8TC_STL/rhipyaw.stl" scale="1 1 1"/>
      </geometry>
      <material name="grey">
        <color rgba="0.35 0.35 0.35 1"/>
      </material>
    </visual>
  </link>
  <joint name="leg1_right" type="revolute">
    <parent link="base"/>
    <child link="rhip_rz"/>
    <origin xyz="0 -0.1 0.03524" rpy="0 0 0"/>
    <axis xyz="0 0 1"/>
    <limit effort="100.0" velocity="100.0" lower="-3.14" upper="3.14"/>
  </joint>
  <link name="rhip_rzrx">
    <inertial>
      <mass value="2.507"/>
      <origin xyz="0.075 0.0 0.0"/>
      <inertia ixx="0.004" ixy="0" ixz="0" iyy="0.003" iyz="0" izz="0.004"/>
    </inertial>
    <visual>
      <origin rpy="0 0 0" xyz="0 0 0"/>
      <geometry>
        <mesh filename="BHR8TC_STL/rhiproll.stl" scale="1 1 1"/>
      </geometry>
      <material name="grey">
        <color rgba="0.35 0.35 0.35 1"/>
      </material>
    </visual>
  </link>
  <joint name="leg2_right" type="revolute">
    <parent link="rhip_rz"/>
    <child link="rhip_rzrx"/>
    <origin xyz="-0.066 0 -0.13924" rpy="0 0 0"/>
    <axis xyz="1 0 0"/>
    <limit effort="100.0" velocity="100.0" lower="-3.14" upper="3.14"/>
  </joint>
  <link name="rthigh">
    <inertial>
      <mass value="3.096"/>
      <origin xyz="0.02 0.0 -0.17"/>
      <inertia ixx="0.040" ixy="0" ixz="0" iyy="0.040" iyz="0" izz="0.006"/>
    </inertial>
    <visual>
      <origin rpy="0 0 0" xyz="0 0 0"/>
      <geometry>
        <mesh filename="BHR8TC_STL/rhippitch.stl" scale="1 1 1"/>
      </geometry>
      <material name="grey">
        <color rgba="0.35 0.35 0.35 1"/>
      </material>
    </visual>
  </link>
  <joint name="leg3_right" type="revolute">
    <parent link="rhip_rzrx"/>
    <child link="rthigh"/>
    <origin xyz="0.077 0.0001 0" rpy="0 0 0"/>
    <axis xyz="0 1 0"/>
    <limit effort="100.0" velocity="100.0" lower="-3.14" upper="3.14"/>
  </joint>
  <link name="rshank">
    <inertial>
      <mass value="1.914"/>
      <origin xyz="0.01 0.0 -0.15"/>
      <inertia ixx="0.02" ixy="0" ixz="0" iyy="0.02" iyz="0" izz="0.002"/>
    </inertial>
    <visual>
      <origin rpy="0 0 0" xyz="0 0 0"/>
      <geometry>
        <mesh filename="BHR8TC_STL/lkneepitch.stl" scale="1 1 1"/>
      </geometry>
      <material name="grey">
        <color rgba="0.35 0.35 0.35 1"/>
      </material>
    </visual>
  </link>
  <joint name="leg4_right" type="revolute">
    <parent link="rthigh"/>
    <child link="rshank"/>
    <origin xyz="0.00754465 0.00336 -0.374943" rpy="0 0 0"/>
    <axis xyz="0 1 0"/>
    <limit effort="100.0" velocity="100.0" lower="-3.14" upper="3.14"/>
  </joint>
  <link name="rankle">
    <inertial>
      <mass value="0.6"/>
      <origin xyz="0.0005146 -4.289e-05 -0.04189"/>
      <inertia ixx="0.002" ixy="0" ixz="0" iyy="0.002" iyz="0" izz="0.0004"/>
    </inertial>
    <visual>
      <origin rpy="0 0 0" xyz="0 0 0"/>
      <geometry>
        <mesh filename="BHR8TC_STL/ranklepitch.stl" scale="1 1 1"/>
      </geometry>
      <material name="light_grey">
        <color rgba="0.75 0.75 0.75 1"/>
      </material>
    </visual>
    <collision>
      <origin rpy="0 0 0" xyz="0.03 0.0 -0.05"/>
      <geometry>
          <box size="0.2 0.1 0.02"/>
      </geometry>
    </collision>
  </link>
  <joint name="leg5_right" type="revolute">
    <parent link="rshank"/>
    <child link="rankle"/>
    <origin xyz="0 0 -0.35" rpy="0 0 0"/>
    <axis xyz="0 1 0"/>
    <limit effort="100.0" velocity="100.0" lower="-3.14" upper="3.14"/>
  </joint>
</robot>